Workbook

Sheet 1. Overview
B4: Informazioni evento e venue | F4: Task Evento | G4: Stato | H4: Owner
B5: Nome Evento | C5: Sundance Sunday | F5: Parametri Evento | G5: Not Started
B6: Orari evento | C6: 12:30 / 22:30 | F6: Device count | G6: Not Started
B7: Orario di arrivo operatori | C7: 11:00 | F7: Menu Prodotti | G7: Not Started
B8: Date Evento | C8: 14/06-05/07-19/07-02/08 | F8: Fiscalità/Stripe | G8: Not Started
B9: Venue | C9: Villa Alberico | F9: Controllo Accessi | G9: Not Started
B10: Indirizzo | C10: Via di Fioranello 18, 00178, Roma | F10: Lineup | G10: Not Started
B11: Indirizzo ingresso staff e parcheggio | C11: Via Appia Antica 400 | G11: Not Started
B12: Indirizzo per spedizione materiali Slesh | G12: Not Started
B13: Capienza massima | C13: 1600
B14: Presenze giornaliere previste | C14: 1600
B16: Referenti
B17: Referente generale
B18: Nome Cognome | C18: Alessandro Proietti
B19: Email | C19: alessandro@dinamicastudio.it
B20: Cellulare | C20: 3383655014
B21: Referente amministrazione per creazione account STRIPE e Fiscalizzazione
B22: Nome Cognome | C22: Alessandro Omodeo
B23: Email | C23: alessandro.omodeo@gmail.com
B24: Cellulare
B25: Referente comunicazione
B26: Nome Cognome | C26: Alessandro Proietti
B27: Email | C27: alessandro@dinamicastudio.it
B28: Cellulare | C28: 3383655014
B29: Altri referenti
B30: Segnalare eventuali altri referenti o contatti utili
B32: Stripe
B33: Ragione sociale | C33: Sundance srls
B34: Email account Stripe
B35: Link modulo Stripe
B37: Bracciali
B38: Quantitativi e tipologie | C38: 1800 x 4 tipologie diverse (7200 in totale)
B39: Indirizzo di consegna | C39: Tv Satellite srl Via Tuscolana 647 Roma, 00174 From Monday to Friday
B40: Contatto destinatario | C40: Marianna Casini +39 340 217 4814
B42: Fiscalità

Sheet 2. Parametri Evento
A1: Tagli ricariche
A2: App operatore/cassa* | B2: 5
A3: *unico taglio
A4: App utente** | B4: 5/10/20/50/100 €
A5: **5 tagli
A6: Importo personalizzato
A7: Importo minimo
A9: Policy rimborsi
A10: Credito minimo per chiedere il rimborso | B10: 1
A11: Costo di gestione del rimborso | B11: 0.5
A12: Tempistiche per richiedere il rimborso* *apertura dopo 24 ore dalla chiusura dell'evento | B12: Dal xx/xx/2026 dalle ore 12:00 | C12: Al xx/xx/2026 alle ore 12:00

Sheet 3. Device Count
A1: Punti di Ricarica | H1: Da compilare - cliente
A2: NOMI PUNTI | B2: # DISPOSITIVI | C2: MENU' | D2: DISPOSITIVO MODELLO | E2: Note | H2: Da compilare - con supporto Slesh
A3: Cassa | B3: 4 | H3: Da compilare - Slesh
A4: Tot dispositivi: | B4: =SUM(B3) -> 4
A6: Punti Bar
A7: NOMI PUNTI | B7: # DISPOSITIVI | C7: MENU' | D7: DISPOSITIVO | E7: Note
A8: MAIN BAR | B8: 9
A9: NO.3 BAR | B9: 1
A10: STAGE BAR | B10: 4
A11: RESP. BAR
A12: Tot dispositivi: | B12: =SUM(B8:B11) -> 14
A14: Food truck
A15: NOMI PUNTI | B15: # DISPOSITIVI | C15: MENU' | D15: DISPOSITIVO | E15: Note
A16: MALANDRINO | B16: 2
A17: SCROCCHIA | B17: 2
A18: PULLED PORK | B18: 2
A19: Tot dispositivi: | B19: =SUM(B16:B18) -> 6
A21: Altro
A22: NOMI PUNTI | B22: # DISPOSITIVI | C22: MENU' | D22: DISPOSITIVO | E22: Note
A23: Accrediti ingresso | B23: 2
A24: Tot dispositivi: | B24: =SUM(B20:B23) -> 2
A26: TOTALE DISPOSITIVI | B26: =B24+B19+B12+B4 -> 26

Sheet 4. Listini Bar
A1: LISTINI PREZZI
F2: Creare una tabella per ciascun negozio con il listino prezzi specifico
A5: MENù PRODOTTI DIVISO PER NEGOZI
A6: Nome | B6: Negozio | C6: Categoria | D6: Prezzo | E6: Iva
A7: Hamburger | B7: Malandrino | C7: Panineria | D7: 12 | E7: 10
A8: Cheeseburger | B8: Malandrino | C8: Panineria | D8: 12 | E8: 10
A9: Veggie Burger | B9: Malandrino | C9: Panineria | D9: 12 | E9: 10
A10: Patatina S | B10: Malandrino | C10: Panineria | D10: 5 | E10: 10
A11: Patatina L | B11: Malandrino | C11: Panineria | D11: 8 | E11: 10
A12: CLASSICA | B12: Scrocchia | C12: Panineria | D12: 7 | E12: 10
A13: SAPORITA | B13: Scrocchia | C13: Panineria | D13: 8 | E13: 10
A14: Pulled | B14: Pulled pork | C14: Panineria | D14: 12 | E14: 10
A15: Veggie | B15: Pulled pork | C15: Panineria | D15: 12 | E15: 10
A16: Fritto | B16: Pulled pork | C16: Panineria | D16: 8 | E16: 10
A17: Birra Heineken | B17: Cocktail Bar | C17: Bar | D17: 7 | E17: 10
A18: Birra Ichnusa | B18: Cocktail Bar | C18: Bar | D18: 8 | E18: 10
... A27: BOTTIGLIA VINO | B27: Cocktail Bar | C27: Bar | D27: 28 | E27: 10
A29: cauzione bicchiere 1€
A32: MENù PRODOTTI COCKTAIL BAR
A33: Nome | B33: Negozio | C33: Categoria | D33: Prezzo | E33: Iva | F33: Cauzione
A34: Cauzione Bicchiere | B34: Cocktail Bar | C34: Bar | D34: 1 | E34: 10
A36: GIN TONIC | B36: Cocktail Bar | C36: Bar | D36: 12 | E36: 10 | F36: FALSE | G36: 1
A37: DRINK | B37: Cocktail Bar | C37: Bar | D37: 12 | E37: 10 | F37: FALSE | G37: 2
A38: SPRITZ | B38: Cocktail Bar | C38: Bar | D38: 10 | E38: 10 | F38: FALSE | G38: 3
A39: SIGNATURE | B39: Cocktail Bar | C39: Bar | D39: 12 | E39: 10 | F39: FALSE | G39: 6
A40: PREMIUM | B40: Cocktail Bar | C40: Bar | D40: 13 | E40: 10 | F40: FALSE | G40: 7
A41: HEINEKEN | B41: Cocktail Bar | C41: Bar | D41: 7 | E41: 10 | F41: FALSE | G41: 4
A42: ICHNUSA NON FILT. | B42: Cocktail Bar | C42: Bar | D42: 8 | E42: 10 | F42: FALSE | G42: 5
A44: PROSECCO | B44: Cocktail Bar | C44: Bar | D44: 7 | E44: 10 | F44: FALSE
A45: VINO | B45: Cocktail Bar | C45: Bar | D45: 7 | E45: 10 | F45: FALSE
A46: BOTTIGLIA VINO | B46: Cocktail Bar | C46: Bar | D46: 28 | E46: 10 | F46: FALSE
A47: BOTTIGLIA PROSECCO | B47: Cocktail Bar | C47: Bar | D47: 28 | E47: 10 | F47: FALSE
A48: BOTTIGLIA METODO CLASSICO | B48: Cocktail Bar | C48: Bar | D48: 36 | E48: 10 | F48: FALSE
A50: SOFT DRINK | B50: Cocktail Bar | C50: Bar | D50: 6 | E50: 10 | F50: FALSE
A51: DRINK ANALCOLICI | B51: Cocktail Bar | C51: Bar | D51: 8 | E51: 10 | F51: FALSE
A52: ACQUA | B52: Cocktail Bar | C52: Bar | D52: 2 | E52: 10 | F52: FALSE
A56: MENù PRODOTTI MALANDRINO
A57: Nome | B57: Negozio | C57: Categoria | D57: Prezzo | E57: Iva | F57: Cauzione
A58: ='4.1. Listini Food'!A7 -> Hamburger | B58: Malandrino | C58: Panineria | D58: ='4.1. Listini Food'!B7 -> 12 | E58: 10 | F58: FALSE
A59: ='4.1. Listini Food'!A8 -> Cheeseburger | B59: Malandrino | C59: Panineria | D59: ='4.1. Listini Food'!B8 -> 12 | E59: 10 | F59: FALSE
...

Sheet 4.1. Listini Food
A1: LISTINI PREZZI
F2: Creare una tabella per ciascun negozio con il listino prezzi specifico
A5: LISTINO PREZZI - MALANDRINO | E5: LISTINO PREZZI - SCROCCHIA
A6: Nome prodotto | B6: Prezzo | C6: Iva | E6: Nome prodotto | F6: Prezzo | G6: Iva
A7: Hamburger | B7: 12 | C7: 0.1 | E7: CLASSICA | F7: 7 | G7: 0.1
A8: Cheeseburger | B8: 12 | C8: 0.1 | E8: SAPORITA | F8: 8 | G8: 0.1
A9: Veggie Burger | B9: 12 | C9: 0.1 | G9: 0.1
A10: Patatina S | B10: 5 | C10: 0.1 | G10: 0.1
A11: Patatina L | B11: 8 | C11: 0.1 | G11: 0.1
C12: 0.1 | G12: 0.1
C13: 0.1 | G13: 0.1
C14: 0.1 | G14: 0.1
A16: LISTINO PREZZI - PULLED PORK
A17: Pulled | B17: 12 | C17: 0.1
A18: Veggie | B18: 12 | C18: 0.1
A19: Fritto | B19: 8 | C19: 0.1
C20: 0.1
C21: 0.1
C22: 0.1

Sheet 5. Lineup
A4: Lineup evento
A6: MAIN STAGE
A7: Data e slot orari | B7: Artista
A8: 45658
A9: 45658
A10: 45658
A11: 45658
A12: 45658
A14: SECONDO STAGE
A15: Data e slot orari | B15: Artista
A16: 45658
A17: 45658
A18: 45658
A19: 45658
A20: 45658
A22: TERZO STAGE
A23: Data e slot orari | B23: Artista
A24: 45658
A25: 45658
A26: 45658
A27: 45658
A28: 45658
